Workbook

Sheet HT
A1: NO | B1: AGGREMENT NUMBER | C1: NAME | D1: ADDRESS | E1: BILLING GROUP | F1: PHONE NUMBER | G1: BOX NO | H1: NO OF BOX | I1: CONTRACTDATE | J1: NIC
A2: 1 | B2: 1150002/1150541 | C2: THANGAMALIGAI NADESAN | D2: NO:38/40 | E2: CIRCULAR ROAD | F2: 763439944/512222319 | H2: 5
A3: 2 | B3: 1150003 | C3: SIVA TELEPRINT | D3: NO:49/5 | E3: CIRCULAR ROAD | F3: 773481900 | G3: 51154 | H3: 1
A4: 3 | B4: 1151325 | C4: N.MANIKAM(NALAI VILAS) | D4: NO:33,SIDE STREET | E4: HATTON TOWN | F4: 729049690 | G4: 459704 | H4: 1
A5: 4 | B5: 1150088 | C5: ASAD | E5: CIRCULAR ROAD | F5: 777536535 | G5: 601539/243126 | H5: 2 | J5: 801652743V
A6: 5 | B6: 1151479 | C6: S.LORANCE | D6: NO:29 | E6: MENDIS MAWATHA | F6: 772634189 | G6: 632615 | H6: 1 | I6: 45763 | J6: 198235401830
A7: 6 | B7: 1150944 | C7: WA.KANCHANA CHANDAMALI | D7: NO:29/18 | E7: MENDIS MAWATHA | F7: 766879035 | G7: 220874 | H7: 1 | I7: 45581 | J7: 885030750V
A8: 7 | B8: 1150848 | C8: C.SIVA (RATHIKA) | D8: NO:88/5 | E8: MENDIS MAWATHA | F8: 770080231 | G8: 291511 | H8: 1 | I8: 45561
A9: 8 | B9: 1150505 | C9: S.IRFAN(STAR SOUND) | D9: NO:227 | E9: DIMBULLA ROAD | F9: 765621201/778707642 | G9: 34440 | H9: 1 | I9: 45203
A10: 9 | B10: 1150023 | C10: SUBOTHINI DHANUJAN[NODE] | D10: NO:23 | E10: MARKET | F10: 770437777 | H10: 1 | J10: 782350161V
A11: 10 | B11: 1150025 | C11: SELVARAJ | D11: NO:19/1,SF RD | E11: MARKET | F11: 775934701 | G11: 232574 | H11: 1 | J11: 607213712X
A12: 11 | B12: 1150199 | C12: DR.SUDHARSHAN | E12: HATTON HOUSE | F12: 771634193 | G12: 530472/517287 | H12: 2 | I12: 45765
A13: 12 | B13: 1150596 | C13: S.BATHMAVATHI | D13: NO:49/A | E13: MENDIS MAWATHA | F13: 776208315 | G13: 127392 | H13: 1 | I13: 45298 | J13: 597561920V
A14: 13 | C14: THIRUCHELVAM | D14: NO:180/12 | E14: HATTON HOUSE | F14: 512225647 | H14: 1
A15: 14 | C15: VAMADEVAN SIR (NODE) | E15: MENDIS MAWATHA | F15: 772645925 | H15: 1
A16: 15 | B16: 1150968 | C16: M.NAGAJOTHY | D16: NO:52A | E16: MENDIS MAWATHA | F16: 777715268 | G16: 265135 | H16: 1 | I16: 45588 | J16: 196384503851
A17: 16 | B17: 1151074 | C17: S.CHANDRAMOHAN | D17: NO:57A | E17: ARIYAGAMA | F17: 766467107/762122835 | G17: 95300 | H17: 1 | I17: 45601
A18: 17 | B18: 1150509 | C18: R.GOKULARAJ | D18: NO:57A | E18: B.TOWN | F18: 701236234/719197316 | G18: 112667 | H18: 1
A19: 18 | B19: 1150964 | C19: M.ANTHONY JAYANTHY | D19: NO:29/11A | E19: MENDIS MAWATHA | F19: 714482149 | G19: 274087 | H19: 1 | I19: 45586
A20: 19 | B20: 1150315 | C20: S.CHANDRAKUMARI | D20: NO:32/62 | E20: B.TOWN | F20: 718556455/713180907 | G20: 665867 | H20: 1 | I20: 45130
A21: 20 | B21: 1151061 | C21: ML.ALIL | D21: NO:13 | E21: HIJIRAPURA | F21: 716584622 | G21: 245822 | H21: 1 | I21: 45601 | J21: 516162279V
A22: 21 | B22: 1150748 | C22: A.PARVATHI | D22: NO:65/5A | E22: MENDIS MAWATHA | F22: 766563082/767688730 | G22: ="0"&91572 -> 091572 | H22: 1 | I22: 45496 | J22: 912590780V
A23: 22 | B23: 1150279 | C23: L.VELAYUDHAM | D23: NO:40A | E23: HIJIRAPURA | F23: 767688730/766563082 | G23: 324644 | H23: 1
A24: 23 | B24: 1150999 | C24: R.PATHMANATHAN(B.SUTHARSHAN) | D24: NO:33/A | E24: SAI STREET | F24: 779590321/777140440 | G24: 320252 | H24: 1 | I24: 45591 | J24: 952840266V
A25: 24 | B25: 1150588 | C25: S.SELVANAYAGAM(TELE STAR) | D25: NO:69/5 | E25: DUNBAR ROAD | F25: 716464058 | G25: 143498 | H25: 1 | I25: 45294 | J25: 651293162V
A26: 25 | B26: 1150133 | C26: MUTHALIF (NODE) | E26: B.TOWN | F26: 713515100 | G26: 276787 | H26: 1 | I26: 44329 | J26: 593542300V
A27: 26 | B27: 1150997 | C27: S.BALASUNDHRAM | D27: NO:79/13 | E27: BJAU KOTTAGE | F27: 779702193 | G27: 306061 | H27: 1 | I27: 45591 | J27: 195807903290
A28: 27 | B28: 1151534 | C28: SIVA SIR | D28: NO:79/15 | E28: BJAU KOTTAGE | F28: 718396848 | G28: 120852 | H28: 1
A29: 28 | B29: 1150513 | C29: G.ABRAHAM | D29: NO:90 | E29: B.TOWN | F29: 775871249 | G29: 148315 | H29: 1 | I29: 45218
A30: 29 | B30: 1150514 | C30: P.SATHIYANATHAN | D30: NO:108/11 | E30: SAMANALAGAMA | F30: 774083007 | G30: 119522 | H30: 1 | I30: 45218
A31: 30 | B31: 1150517 | C31: R.NANDHAKUMAR | D31: NO:295/1/1 | E31: DIMBULLA ROAD | F31: 773848617 | G31: 111362 | H31: 1 | I31: 45222
A32: 31 | B32: 1150026 | C32: KUMARASAMY | D32: NO:77E | E32: BJAU KOTTAGE | F32: 770699564/705300000 | G32: 493035 | H32: 1
A33: 32 | B33: 1150612 | C33: KOMATHY GANESHAN | D33: NO:81 | E33: BJAU KOTTAGE | F33: 512222392 | G33: ="0"&87406 -> 087406 | H33: 1 | I33: 45307 | J33: 196550900312
A34: 33 | B34: 1150044 | C34: HATTON PRINTERS | D34: NO:4 | E34: DUMBRUGIRIYA | F34: 776009120 | G34: 563549 | H34: 1
A35: 34 | B35: 1150794 | C35: SHARMILA | D35: NO:79/3 | E35: BJAU KOTTAGE | F35: 777797963/512224906 | G35: ="0"&61450 -> 061450 | H35: 1 | I35: 45531 | J35: 198079703207
A36: 35 | B36: 1150319 | C36: P.CHANDRASEKARAN | E36: CIRCULAR ROAD | F36: 778833582 | G36: 646972 | H36: 1
A37: 36 | B37: 1150675 | C37: M.SELVATHURAI | D37: NO:5,NHS | E37: DUMBRUGIRIYA | F37: 512222913 | G37: 141674 | H37: 1 | I37: 45416 | J37: 492972649V
A38: 37 | B38: 1150520 | C38: S.KARTHISVARAN | D38: NO:93/A | E38: DUMBRUGIRIYA | F38: 779579366 | G38: 115694 | H38: 1
A39: 38 | B39: 1151044 | C39: RAVI TAILOR SHOP | E39: BJAU KOTTAGE | F39: 777517347 | G39: 333438 | H39: 1 | I39: 45599 | J39: 741450674V
A40: 39 | B40: 1150522 | C40: C.SIVARAJA MAYURAN | E40: B.TOWN | F40: 714333052/757512306 | G40: 24599 | H40: 1 | I40: 45236
...

Sheet ESTATE
A1: NO | B1: AGGREMENT NUMBER | C1: NAME | D1: BILLING GROUP | E1: PHONE | F1: BOX NO | G1: NO OF BOX | H1: CONTRACTDATE | I1: CONTRACTDATE | J1: NIC
A2: 1 | B2: 1150012 | C2: VIGNESH (NODE) | D2: 50 ACER | E2: 765737397/754631194 | F2: 272868 | G2: 1 | H2: 45566
A3: 2 | B3: 1151148 | C3: R.SIVAKUMAR | D3: 50 ACER | E3: 774497524 | F3: 349038 | G3: 1 | H3: 45605 | J3: 441943130X
A4: 3 | B4: 1151147 | C4: S.VIGNESWARAN(PRIYA) | D4: 50 ACER | E4: 768495577/760351414/751619026 | F4: 267057 | G4: 1 | H4: 45606
A5: 4 | D5: 50 ACER
A6: 5 | B6: 1151154 | C6: M.THAYALAN | D6: 50 ACER | E6: 764448344 | F6: 192735 | G6: 1 | H6: 45605
A7: 6 | B7: 1151272 | C7: S.MOORTHY | D7: 50 ACER | E7: 778385466 | F7: 281223 | G7: 1 | H7: 45610
A8: 7 | B8: 1151159 | C8: V.CHANDRAKUMAR | D8: 50 ACER | E8: 764010656/761742113 | F8: 346273 | G8: 1 | H8: 45605
A9: 8 | D9: 50 ACER
A10: 9 | D10: 50 ACER
A11: 10 | B11: 1151567 | C11: R.SUTHA | D11: 50 ACER | E11: 772423006 | F11: 606064 | G11: 1 | H11: 45878
A12: 11 | B12: 1151172 | C12: S.MUNIYANDY | D12: 50 ACER | E12: 767599819 | F12: 389463 | G12: 1 | H12: 45606 | J12: 788066197V
A13: 12 | B13: 1151157 | C13: B.BALA | D13: 50 ACER | E13: 775000703 | F13: 185978 | G13: 1 | H13: 45605
A14: 13 | B14: 1151348 | C14: K.RAMESH (R.NESHANTHINI) | D14: 50 ACER | E14: 751260128/712386048 | F14: 417314 | G14: 1 | H14: 45684 | J14: 885161359V
A15: 14 | B15: 1151155 | C15: R.PRASHANTH | D15: 50 ACER | E15: 770848659 | F15: 298144 | G15: 1 | H15: 45605
A16: 15 | B16: 1151156 | C16: B.PATHMANATHAN | D16: 50 ACER | E16: 772590415/779749476 | F16: 231178 | G16: 1 | H16: 45605
A17: 16 | D17: 50 ACER
A18: 17 | B18: 1151158 | C18: S.SATHEES | D18: 50 ACER | E18: 772423006 | F18: 426349 | G18: 1 | H18: 45605
A19: 18 | B19: 1151150 | C19: S.PRADEEP | D19: 50 ACER | E19: 761177441 | F19: 277452 | G19: 1 | H19: 45606
A20: 19 | D20: 50 ACER
A21: 20 | D21: 50 ACER
A22: 21 | D22: 50 ACER
A23: 22 | D23: 50 ACER
A24: 23 | B24: 1151104 | C24: S.MANSUBIKHAN | D24: 50 ACER | E24: 756847694/774997880 | F24: 455314 | G24: 1 | H24: 45603 | J24: 860252953V
A25: 24 | B25: 1151149 | C25: M.NAGULESHVARAN | D25: 50 ACER | E25: 768687329 | F25: 194939 | G25: 1 | H25: 45605 | J25: 198627010034
A26: 1 | B26: 1150332 | C26: A.GANESHARATNAM | D26: ABBOTSLIGH | E26: 777519204 | F26: 278718 | G26: 1
A27: 2 | B27: 1150854 | C27: KALIYAPPAN DEVI | D27: ABBOTSLIGH | F27: 123953 | G27: 1 | H27: 45565
A28: 3 | D28: ABBOTSLIGH
A29: 4 | B29: 1150287 | C29: DIPA MOHANRAJ | D29: ABBOTSLIGH | E29: 774630388/767476854 | F29: 690715 | G29: 1 | J29: 971920602V
A30: 5 | D30: ABBOTSLIGH
A31: 6 | B31: 1150632 | C31: MAHESHWARAN SATHYA SEELAN | D31: ABBOTSLIGH | E31: 764598820/515688307 | F31: ="0"&54067 -> 054067 | G31: 1 | H31: 45323 | J31: 941022715V
A32: 7 | D32: ABBOTSLIGH
A33: 8 | B33: 1150920 | C33: RATNAVEL GOBINATH | D33: ABBOTSLIGH | E33: 779953183 | F33: ="0"&80062 -> 080062 | G33: 1 | H33: 45577 | J33: 198617802875
A34: 9 | D34: ABBOTSLIGH
A35: 10 | D35: ABBOTSLIGH
A36: 11 | B36: 1150348 | C36: V.MUNUSAMY KANDHAIYA | D36: ABBOTSLIGH | E36: 721417752 | F36: 580659 | G36: 1 | I36: 44730 | J36: 670932796X
A37: 12 | D37: ABBOTSLIGH
A38: 13 | B38: 1150433 | C38: SILAMBARAM PRABAGARAN | D38: ABBOTSLIGH | E38: 742778960 | F38: 128051 | G38: 1 | H38: 44984 | I38: 44984 | J38: 198419502073
A39: 14 | B39: 1150308 | C39: S.DHAYA | D39: ABBOTSLIGH | E39: 769039144 | F39: 590987 | G39: 1 | H39: 45814 | J39: 920823610V
A40: 15 | B40: 1150701 | C40: SATHYA KUMAR KUTTY | D40: ABBOTSLIGH | F40: ="0"&90038 -> 090038 | G40: 1 | H40: 45466 | J40: 952563270V
...

Sheet BOX DETAILS
A1: BOX DETAILS | E1: BILLING DATE CYCLE
A2: NO | B2: BILLING GROUP | C2: NO OF CONNECTION | D2: AREA | E2: billing_start | F2: billing_end
A3: 1 | B3: 50 ACER | C3: =SUM(ESTATE!G2:G25) -> 16 | D3: 50 ACER | E3: 10 | F3: 15
A4: 2 | B4: ABBOTSLIGH | C4: =SUM(ESTATE!G26:G123) -> 62 | D4: ABBOTSLIGH | E4: 10 | F4: 15
A5: 3 | B5: BRODUC | C5: =SUM(ESTATE!G124:G179) -> 32 | D5: BRODUC | E5: 10 | F5: 15
A6: 4 | B6: COMMERCIAL | C6: =SUM(ESTATE!G180:G192) -> 23 | D6: COMMERCIAL | E6: 10 | F6: 15
A7: 5 | B7: DUNBAR LD | C7: =SUM(ESTATE!G193:G252) -> 26 | D7: DUNBAR LD | E7: 10 | F7: 15
A8: 6 | B8: DUNBAR UD | C8: =SUM(ESTATE!G253:G377) -> 74 | D8: DUNBAR UD | E8: 10 | F8: 15
A9: 7 | B9: DUNBAR SKEAM | C9: =SUM(ESTATE!G378:G386) -> 9 | D9: DUNBAR SKEAM | E9: 10 | F9: 15
A10: 8 | B10: FLORENCE | C10: =SUM(ESTATE!G388:G446) -> 35 | D10: FLORENCE | E10: 10 | F10: 15
A11: 9 | B11: HATTON ES | C11: =SUM(ESTATE!G447:G581) -> 63 | D11: HATTON ES | E11: 10 | F11: 15
A12: 10 | B12: MALBROUGH | C12: =SUM(ESTATE!G582:G721) -> 40 | D12: MALBROUGH | E12: 10 | F12: 15
A13: 11 | B13: MALIYAPU ES | C13: =SUM(ESTATE!G722:G798) -> 52 | D13: MALIYAPU ES | E13: 10 | F13: 15
A14: 12 | B14: MARSK | C14: =SUM(ESTATE!G799:G921) -> 85 | D14: MARSK | E14: 10 | F14: 15
A15: 13 | B15: MONTIFIOR | C15: =SUM(ESTATE!G922:G1027) -> 62 | D15: MONTIFIOR | E15: 10 | F15: 15
A16: 14 | B16: PANMURE | C16: =SUM(ESTATE!G1028:G1207) -> 77 | D16: PANMURE | E16: 10 | F16: 15
A17: 15 | B17: STRATHON | C17: =SUM(ESTATE!G1208:G1385) -> 95 | D17: STRATHON | E17: 10 | F17: 15
A18: 17 | B18: APPROCH ROAD FRUTILL | C18: =COUNTIF(HT!E2:E1011,"APPROCH ROAD FRUTILL") -> 1 | D18: HATTON | E18: 20 | F18: 25
A19: 18 | B19: ARIYAGAMA | C19: =COUNTIF(HT!E2:E1011,"ARIYAGAMA") -> 62 | D19: HATTON | E19: 20 | F19: 25
A20: 19 | B20: B.TOWN | C20: =COUNTIF(HT!E2:E1011,"B.TOWN") -> 107 | D20: HATTON | E20: 20 | F20: 25
A21: 20 | B21: BJAU KOTTAGE | C21: =COUNTIF(HT!E2:E1011,"BJAU KOTTAGE") -> 30 | D21: HATTON | E21: 20 | F21: 25
A22: 21 | B22: BUS STAND | C22: =COUNTIF(HT!E2:E1011,"BUS STAND") -> 15 | D22: HATTON | E22: 20 | F22: 25
A23: 22 | B23: CIRCULAR ROAD | C23: =COUNTIF(HT!E2:E1011,"CIRCULAR ROAD") -> 66 | D23: HATTON | E23: 20 | F23: 25
A24: 23 | B24: DEPPOT ROAD | C24: =COUNTIF(HT!E2:E1011,"DEPPOT ROAD") -> 7 | D24: HATTON | E24: 20 | F24: 25
A25: 24 | B25: DICKOYA HOSPITAL | C25: =COUNTIF(HT!E2:E1011,"DICKOYA HOSPITAL") -> 3 | D25: HATTON | E25: 20 | F25: 25
A26: 25 | B26: DICKOYA ROAD | C26: =COUNTIF(HT!E2:E1011,"DICKOYA ROAD") -> 3 | D26: HATTON | E26: 20 | F26: 25
A27: 26 | B27: DIMBULLA ROAD | C27: =COUNTIF(HT!E2:E1011,"DIMBULLA ROAD") -> 60 | D27: HATTON | E27: 20 | F27: 25
A28: 27 | B28: DUMBRUGIRIYA | C28: =COUNTIF(HT!E2:E1011,"DUMBRUGIRIYA") -> 50 | D28: HATTON | E28: 20 | F28: 25
A29: 28 | B29: DUNBAR ROAD | C29: =COUNTIF(HT!E2:E1011,"DUNBAR ROAD") -> 52 | D29: HATTON | E29: 20 | F29: 25
A30: 29 | B30: HATTON HOUSE | C30: =COUNTIF(HT!E2:E1011,"HATTON HOUSE") -> 2 | D30: HATTON | E30: 20 | F30: 25
A31: 30 | B31: HATTON POLICE | C31: =COUNTIF(HT!E2:E1011,"HATTON POLICE") -> 8 | D31: HATTON | E31: 20 | F31: 25
A32: 31 | B32: HATTON TOWN | C32: =COUNTIF(HT!E2:E1011,"HATTON TOWN") -> 16 | D32: HATTON | E32: 20 | F32: 25
A33: 32 | B33: HIJIRAPURA | C33: =COUNTIF(HT!E2:E1011,"HIJIRAPURA") -> 100 | D33: HATTON | E33: 20 | F33: 25
A34: 33 | B34: HILL STREET | C34: =COUNTIF(HT!E2:E1011,"HILL STREET") -> 17 | D34: HATTON | E34: 20 | F34: 25
A35: 34 | B35: KANDHAIYA BUILDING | C35: =COUNTIF(HT!E2:E1011,"KANDHAIYA BUILDING") -> 13 | D35: HATTON | E35: 20 | F35: 25
A36: 35 | B36: MAIN STREET | C36: =COUNTIF(HT!E2:E1011,"MAIN STREET") -> 1 | D36: HATTON | E36: 20 | F36: 25
A37: 36 | B37: MALLIYAPU TOWN | C37: =COUNTIF(HT!E2:E1011,"MALLIYAPU TOWN") -> 9 | D37: HATTON | E37: 20 | F37: 25
A38: 37 | B38: MARKET | C38: =COUNTIF(HT!E2:E1011,"MARKET") -> 18 | D38: HATTON | E38: 20 | F38: 25
A39: 38 | B39: MENDIS MAWATHA | C39: =COUNTIF(HT!E2:E1011,"MENDIS MAWATHA") -> 34 | D39: HATTON | E39: 20 | F39: 25
A40: 39 | B40: MR TOWN | C40: =COUNTIF(HT!E2:E1011,"MR TOWN") -> 8 | D40: HATTON | E40: 20 | F40: 25
...

Sheet SMR
A1: NO | B1: A-G NO | C1: NAME | D1: ESTATE | E1: TP | F1: BOX NO | G1: NO OF BOX | H1: CON DATE | I1: Box owners
A2: 1 | B2: 1150847 | C2: MD.POONGANTHA KUMARAVELPURAM | D2: PATHANA | E2: 754034610/752061370 | F2: 281280 | G2: 1 | H2: 45561 | I2: AG
A3: 2 | B3: 1150873 | C3: RANGARAJA SIVAKUMAR | D3: PATHANA | E3: 772321807 | F3: 360084 | G3: 1 | H3: 45571 | I3: AG
A4: 3 | B4: 1150883 | C4: NALLASEGARAM CHANDRAMOHAN | D4: PATHANA | E4: 778255452 | F4: 187800 | G4: 1 | H4: 45573 | I4: AG
A5: 4 | B5: 1150885 | C5: MUTHAIYA PUSHPARAJ | D5: SMR | E5: 76609014 | F5: 188774 | G5: 1 | H5: 45574 | I5: AG
A6: 5 | B6: 1150886 | C6: MUTHAIYA KUMARASAMI | D6: SMR | E6: 769959594 | F6: 357213 | G6: 1 | H6: 45574 | I6: AG
A7: 6 | B7: 1150887 | C7: M.SHANMUGAM | E7: 763048013 | F7: 390818 | G7: 1 | H7: 45574 | I7: AG
A8: 7 | B8: 1150888 | C8: V.SASIKALA | E8: 756213409 | F8: 293228 | G8: 1 | H8: 45574 | I8: AG
A9: 8 | B9: 1150889 | C9: V.KAMALADHASAN | E9: 759474006 | F9: 207483 | G9: 1 | H9: 45574 | I9: AG
A10: 9 | B10: 1150890 | C10: SUBRAMANIYAM KOGILAMANI | E10: 761678257 | F10: 269673 | G10: 1 | H10: 45574 | I10: AG
A11: 10 | B11: 1150891 | C11: R.DHUVAN (RAJARATHNAM) | E11: 761894496 | F11: 214471 | G11: 1 | H11: 45574 | I11: AG
A12: 11 | B12: 1150892 | C12: S.LALITHA | E12: 778024266 | F12: 399116 | G12: 1 | H12: 45574 | I12: AG
A13: 12 | B13: 1150893 | C13: RAJARATHNAM SUNDHARAJ | F13: 441710 | G13: 1 | H13: 45574 | I13: AG
A14: 13 | B14: 1150894 | C14: S.ALAGURAJA | E14: 774554240 | F14: 251523 | G14: 1 | H14: 45574 | I14: AG
A15: 14 | B15: 1150895 | C15: V.KRISHNAMENAN | E15: 764178450 | F15: 411580 | G15: 1 | H15: 45574 | I15: AG
A16: 15 | B16: 1150896 | C16: RAMAJEYAM RANJINI | E16: 72363316 | F16: 180789 | G16: 1 | H16: 45574 | I16: AG
A17: 16 | B17: 1150897 | C17: PERUMAL MAGESHVAR | E17: 772686788 | F17: 450562 | G17: 1 | H17: 45574 | I17: AG
A18: 17 | B18: 1150898 | C18: I.DIVYA | E18: 759389096 | F18: 282536 | G18: 1 | H18: 45574 | I18: AG
A19: 18 | B19: 1150899 | C19: THIYAGARAJ MADASAMI | E19: 778872194 | F19: 201577 | G19: 1 | H19: 45574 | I19: AG
A20: 19 | B20: 1150900 | C20: B.MANOPRIYA | E20: 774869511 | F20: 247117 | G20: 1 | H20: 45574 | I20: AG
A21: 20 | B21: 1150907 | C21: VELU YOGA SENTHAMIL | E21: 769374923 | F21: 223811 | G21: 1 | H21: 45577 | I21: AG
A22: 21 | B22: 1220458 | C22: A.YOGARAJ | E22: 761615718 | F22: 238447 | G22: 1 | H22: 45583 | I22: PK
A23: 22 | B23: 1220457 | C23: RAMAIYA NAGARAJA | E23: 767199866 | F23: 386444 | G23: 1 | H23: 45583 | I23: PK
A24: 23 | B24: 1220459 | C24: SRIKANTH | E24: 77346623 | F24: 379944 | G24: 1 | H24: 45583 | I24: PK
A25: 24 | B25: 1220466 | C25: S.VELLADHURAI | E25: 741604165 | F25: 196140 | G25: 1 | H25: 45583 | I25: PK
... A28: 27 | B28: 1220491 | C28: S.SELVARAJ | E28: 775981673 | F28: 229750 | G28: 1 | H28: 45585 | I28: PK
A29: 28 | B29: 1220505 | C29: V.KIRUBAKARAN | F29: 443567 | G29: 1 | H29: 45585 | I29: PK
A30: 29 | B30: 1220524 | C30: G.PUVANESWARAN | E30: 779532439 | F30: 391709 | G30: 1 | H30: 45587 | I30: PK
A31: 30 | B31: 1220588 | C31: VIJANTHIRAN | E31: 767269394 | F31: 373004 | G31: 1 | H31: 45590 | I31: PK
A32: 31 | B32: 1220589 | C32: PRASHANTHAN | H32: 45590
A33: 32 | B33: 1220615 | C33: JEYANTHAMARY | E33: 740598881 | H33: 45592
A34: 33 | B34: 1220616 | C34: G.SIVARAJA | E34: 763340847 | F34: 263858 | G34: 1 | H34: 45592 | I34: PK
A35: 34 | B35: 1220623 | C35: RAMAKRISHNAN | E35: 776878484 | F35: 248966 | G35: 1 | H35: 45592 | I35: PK
A36: 35 | B36: 1220632 | C36: ARUMUGAM BALAKRISHNAN | E36: 776501337 | F36: 163926 | G36: 1 | H36: 45592 | I36: PK
A37: 36 | B37: 1220633 | C37: ARUMUGAM KRISHNAKUMAR | E37: 776501337 | F37: 258817 | G37: 1 | H37: 45592 | I37: PK
A38: 37 | B38: 1220634 | C38: PERIYASAMY MARUTHAMUTHU | E38: 776501337 | F38: 335920 | G38: 1 | H38: 45592 | I38: PK
A39: 38 | B39: 1220637 | C39: CHANDRABOSE | E39: 702895818 | F39: 343601 | G39: 1 | H39: 45592 | I39: PK
A40: 39 | B40: 1220639 | C40: S.YOGARAJA | E40: 775496052 | F40: 258049 | G40: 1 | H40: 45592 | I40: PK
A41: 40 | B41: 1220650 | C41: VIGNESHWARAN | E41: 771382212 | F41: 354129 | G41: 1 | H41: 45592 | I41: PK
A42: 41 | B42: 1220658 | C42: N.VIJAYANTHINI | E42: 765423187 | F42: 396203 | G42: 1 | H42: 45593 | I42: PK
...
